Workbook

Sheet Income Statement
A1: Assumtions
A2: Tax | B2: 0.1
A3: Cost of Capital | B3: 0.2
A4: NWC | B4: 0.15
A5: Growth Rate | B5: 0.03
A6: Margin | B6: 0.4
A7: Number of Patients per year | B7: 240
A8: Increase in Number of Patients | B8: 60
A9: Increase in Salary | B9: 0.05
A10: Increase in Other Expenses | B10: 0.07
A11: Decrease on Advertisment | B11: 0.07
A12: Cost of Rent per m2 | B12: 10$
A13: Bronze Package | B13: 0.6
A14: Silver Package | B14: 0.3
A15: Gold Package | B15: 0.1
A17: Income Statement | C17: All data in dollars
A19: Year | B19: 0 | C19: 1 | D19: 2 | E19: 3 | F19: 4 | G19: 5
A20: Sales | C20: ='Gross Income'!B46 -> 389636 | D20: ='Gross Income'!C46 -> 484783 | E20: ='Gross Income'!D46 -> 579930 | F20: ='Gross Income'!E46 -> 675077 | G20: ='Gross Income'!F46 -> 779272
A21: COGS | C21: =-'Gross Income'!I46 -> -278245 | D21: =-'Gross Income'!J46 -> -346190.5 | E21: =-'Gross Income'!K46 -> -414136 | F21: =-'Gross Income'!L46 -> -482081.5 | G21: =-'Gross Income'!M46 -> -556490
A22: Gross Profit | C22: =C20+C21 -> 111391 | D22: =D20+D21 -> 138592.5 | E22: =E20+E21 -> 165794 | F22: =F20+F21 -> 192995.5 | G22: =G20+G21 -> 222782
A23: Operating Expences
A24: Salaries | C24: =-'Operating Expences'!B34 -> -55800 | D24: =-'Operating Expences'!C34 -> -58590 | E24: =-'Operating Expences'!D34 -> -116424 | F24: =-'Operating Expences'!E34 -> -122245.2 | G24: =-'Operating Expences'!F34 -> -138567.71
A25: Rent | C25: =-'Operating Expences'!B39 -> -7680 | D25: =-'Operating Expences'!C39 -> -7680 | E25: =-'Operating Expences'!D39 -> -7680 | F25: =-'Operating Expences'!E39 -> -12000 | G25: =-'Operating Expences'!F39 -> -12000
A26: Advertisment | C26: =-'Operating Expences'!B40 -> -12000 | D26: =-'Operating Expences'!C40 -> -11160 | E26: =-'Operating Expences'!D40 -> -10378.8 | F26: =-'Operating Expences'!E40 -> -9652.284 | G26: =-'Operating Expences'!F40 -> -8976.6241
A27: Depreciation | C27: =-'Operating Expences'!B50 -> -4744 | D27: =-'Operating Expences'!C50 -> -4744 | E27: =-'Operating Expences'!D50 -> -5808 | F27: =-'Operating Expences'!E50 -> -5808 | G27: =-'Operating Expences'!F50 -> -5988
A28: Other | C28: =-'Operating Expences'!B41 -> -4200 | D28: =-'Operating Expences'!C41 -> -4494 | E28: =-'Operating Expences'!D41 -> -4808.58 | F28: =-'Operating Expences'!E41 -> -5145.1806 | G28: =-'Operating Expences'!F41 -> -5505.3432
A29: Total Expences | C29: =SUM(C24:C28) -> -84424 | D29: =SUM(D24:D28) -> -86668 | E29: =SUM(E24:E28) -> -145099.38 | F29: =SUM(F24:F28) -> -154850.66 | G29: =SUM(G24:G28) -> -171037.68
A30: EBIT | C30: =C22+C29 -> 26967 | D30: =D22+D29 -> 51924.5 | E30: =E22+E29 -> 20694.62 | F30: =F22+F29 -> 38144.835 | G30: =G22+G29 -> 51744.32
A31: Taxes | C31: =-C30*$B$2 -> -2696.7 | D31: =-D30*$B$2 -> -5192.45 | E31: =-E30*$B$2 -> -2069.462 | F31: =-F30*$B$2 -> -3814.4835 | G31: =-G30*$B$2 -> -5174.432
A32: Net Income | C32: =C30+C31 -> 24270.3 | D32: =D30+D31 -> 46732.05 | E32: =E30+E31 -> 18625.158 | F32: =F30+F31 -> 34330.352 | G32: =G30+G31 -> 46569.888
A34: Free Cash Flow Adjustment
B36: 0 | C36: 1 | D36: 2 | E36: 3 | F36: 4 | G36: 5 | I36: Year | J36: Free Cash Flow | K36: Cumulative
A37: Unlevered Net Income | C37: =C32 -> 24270.3 | D37: =D32 -> 46732.05 | E37: =E32 -> 18625.158 | F37: =F32 -> 34330.352 | G37: =G32 -> 46569.888 | I37: 0 | J37: =B41 -> -60220 | K37: =J37 -> -60220
A38: Depreciation | C38: =-C27 -> 4744 | D38: =-D27 -> 4744 | E38: =-E27 -> 5808 | F38: =-F27 -> 5808 | G38: =-G27 -> 5988 | I38: 1 | J38: =C41 -> -29431.1 | K38: =K37+J38 -> -89651.1
A39: CapEx | B39: =-'Operating Expences'!B59 -> -60220 | C39: =-'Operating Expences'!C59 -> 0 | D39: =-'Operating Expences'!D59 -> -6570 | E39: =-'Operating Expences'!E59 -> 0 | F39: =-'Operating Expences'!F59 -> -1150 | G39: =-'Operating Expences'!G59 -> 0 | I39: 2 | J39: =D41 -> 30634 | K39: =K38+J39 -> -59017.1
A40: NWC | C40: =C50 -> -58445.4 | D40: =D50 -> -14272.05 | E40: =E50 -> -14272.05 | F40: =F50 -> -14272.05 | G40: =G50 -> -15629.25 | I40: 3 | J40: =E41 -> 10161.108 | K40: =K39+J40 -> -48855.992
A41: FCF | B41: =SUM(B37:B40) -> -60220 | C41: =SUM(C37:C40) -> -29431.1 | D41: =SUM(D37:D40) -> 30634 | E41: =SUM(E37:E40) -> 10161.108 | F41: =SUM(F37:F40) -> 24716.302 | G41: =SUM(G37:G40) -> 36928.638 | I41: 4 | J41: =F41 -> 24716.302 | K41: =K40+J41 -> -24139.69
A42: TV | G42: =(G41*(1+B5))/(B3-B5) -> 223744.1 | I42: 5 | J42: =G41 -> 36928.638 | K42: =K41+J42 -> 12788.948
A43: FCF with TV | B43: =SUM(B41:B42) -> -60220 | C43: =SUM(C41:C42) -> -29431.1 | D43: =SUM(D41:D42) -> 30634 | E43: =SUM(E41:E42) -> 10161.108 | F43: =SUM(F41:F42) -> 24716.302 | G43: =SUM(G41:G42) -> 260672.74
A44: DCF | B44: =B43/(1+$B$3)^B36 -> -60220 | C44: =C43/(1+$B$3)^C36 -> -24525.917 | D44: =D43/(1+$B$3)^D36 -> 21273.611 | E44: =E43/(1+$B$3)^E36 -> 5880.2708 | F44: =F43/(1+$B$3)^F36 -> 11919.513 | G44: =G43/(1+$B$3)^G36 -> 104758.53
...

Sheet Operating Expences
A1: Salary | B1: 0 | C1: 1 | D1: 2 | E1: 3 | F1: 4 | G1: 5
A3: Positions | B3: Salary per Year | C3: Year 1 | D3: Year 2 | E3: Year 3 | F3: Year 4 | G3: Year 5
A4: Coordinator | B4: 8400 | C4: 2 | D4: 2 | E4: 4 | F4: 4 | G4: 5 | H4: Reference
A5: Accountant | B5: 9000 | C5: 1 | D5: 1 | E5: 2 | F5: 2 | G5: 2 | H5: Reference
A6: Marketing & PR Specialist | B6: 6600 | C6: 1 | D6: 1 | E6: 2 | F6: 2 | G6: 2 | H6: Reference
A7: Sales Manager | B7: 9000 | C7: 1 | D7: 1 | E7: 2 | F7: 2 | G7: 2 | H7: Reference
A8: Office Manager | B8: 6000 | C8: 1 | D8: 1 | E8: 1 | F8: 1 | G8: 1 | H8: Reference
A9: Guide | B9: 4200 | C9: 2 | D9: 2 | E9: 4 | F9: 4 | G9: 4 | H9: Reference
A11: Fixed Assets
A13: Assets | B13: Cost | C13: Usefull Life in Year | D13: Depriciation | E13: Year 1 | F13: Year 2 | G13: Year 3 | H13: Year 4 | I13: Year 5
A14: Computer | B14: 650 | C14: 5 | D14: =B14/C14 -> 130 | E14: =SUM(C4:C8) -> 6 | F14: =SUM(D4:D8) -> 6 | G14: =SUM(E4:E8) -> 11 | H14: =SUM(F4:F8) -> 11 | I14: =SUM(G4:G8) -> 12 | J14: Reference
A15: Printer | B15: 410 | C15: 5 | D15: =B15/C15 -> 82 | E15: =ROUND(E14/3,0) -> 2 | F15: =ROUND(F14/3,0) -> 2 | G15: =ROUND(G14/3,0) -> 4 | H15: =ROUND(H14/3,0) -> 4 | I15: =ROUND(I14/3,0) -> 4 | J15: Reference
A16: Office Furniture Set | B16: 500 | C16: 10 | D16: =B16/C16 -> 50 | E16: =E14 -> 6 | F16: =F14 -> 6 | G16: =G14 -> 11 | H16: =H14 -> 11 | I16: =I14 -> 12 | J16: Reference
A17: Vehicle | B17: 52500 | C17: 15 | D17: =B17/C17 -> 3500 | E17: 1 | F17: 1 | G17: 1 | H17: 1 | I17: 1 | J17: Reference
A19: Rent
A21: Area in m^2 | B21: Cost per m^2 | C21: Cost per year
A22: 32 | B22: =20 -> 20 | C22: =A22*12*B22 -> 7680 | D22: An average cost of rent is lower than 10 USD. We took highest value to neglect possible increasing in rent
A23: 50 | B23: 20 | C23: =A23*12*B23 -> 12000
A25: Salary Expences
A27: Positions | B27: Year 1 | C27: Year 2 | D27: Year 3 | E27: Year 4 | F27: Year 5 | G27: 0.05
A28: =A4 -> Coordinator | B28: =C4*$B4*((1+$G$27)^$B1) -> 16800 | C28: =D4*$B$4*((1+$G$27)^C1) -> 17640 | D28: =E4*$B$4*((1+$G$27)^D1) -> 37044 | E28: =F4*$B$4*((1+$G$27)^E1) -> 38896.2 | F28: =G4*$B$4*((1+$G$27)^F1) -> 51051.262 | G28: Increasing of salary by 5%
A29: =A5 -> Accountant | B29: =C5*$B5*((1+$G$27)^B$1) -> 9000 | C29: =D5*$B5*((1+$G$27)^C1) -> 9450 | D29: =E5*$B5*((1+$G$27)^D1) -> 19845 | E29: =F5*$B5*((1+$G$27)^E1) -> 20837.25 | F29: =G5*$B5*((1+$G$27)^F1) -> 21879.112
A30: =A6 -> Marketing & PR Specialist | B30: =C6*$B6*((1+$G$27)^B1) -> 6600 | C30: =D6*$B6*((1+$G$27)^C1) -> 6930 | D30: =E6*$B6*((1+$G$27)^D1) -> 14553 | E30: =F6*$B6*((1+$G$27)^E1) -> 15280.65 | F30: =G6*$B6*((1+$G$27)^F1) -> 16044.683
A31: =A7 -> Sales Manager | B31: =C7*$B7*((1+$G$27)^B1) -> 9000 | C31: =D7*$B7*((1+$G$27)^C1) -> 9450 | D31: =E7*$B7*((1+$G$27)^D1) -> 19845 | E31: =F7*$B7*((1+$G$27)^E1) -> 20837.25 | F31: =G7*$B7*((1+$G$27)^F1) -> 21879.112
A32: =A8 -> Office Manager | B32: =C8*$B8*((1+$G$27)^B1) -> 6000 | C32: =D8*$B8*((1+$G$27)^C1) -> 6300 | D32: =E8*$B8*((1+$G$27)^D1) -> 6615 | E32: =F8*$B8*((1+$G$27)^E1) -> 6945.75 | F32: =G8*$B8*((1+$G$27)^F1) -> 7293.0375
A33: =A9 -> Guide | B33: =C9*$B9*((1+$G$27)^B1) -> 8400 | C33: =D9*$B9*((1+$G$27)^C1) -> 8820 | D33: =E9*$B9*((1+$G$27)^D1) -> 18522 | E33: =F9*$B9*((1+$G$27)^E1) -> 19448.1 | F33: =G9*$B9*((1+$G$27)^F1) -> 20420.505
A34: Total | B34: =SUM(B28:B33) -> 55800 | C34: =SUM(C28:C33) -> 58590 | D34: =SUM(D28:D33) -> 116424 | E34: =SUM(E28:E33) -> 122245.2 | F34: =SUM(F28:F33) -> 138567.71
A36: Other Expences
B38: Year 1 | C38: Year 2 | D38: Year 3 | E38: Year 4 | F38: Year 5 | G38: 0.07
A39: Rent | B39: =C22 -> 7680 | C39: =B39 -> 7680 | D39: =C39 -> 7680 | E39: =C23 -> 12000 | F39: =E39 -> 12000
A40: Advertisment | B40: 12000 | C40: =B40*(1-$G$38) -> 11160 | D40: =C40*(1-$G$38) -> 10378.8 | E40: =D40*(1-$G$38) -> 9652.284 | F40: =E40*(1-$G$38) -> 8976.6241 | G40: Reducing advertising costs through word of mouth
A41: Other | B41: 4200 | C41: =B41*(1+$G$38) -> 4494 | D41: =C41*(1+$G$38) -> 4808.58 | E41: =D41*(1+$G$38) -> 5145.1806 | F41: =E41*(1+$G$38) -> 5505.3432 | G41: The increase in prices due to the increase in patients
A43: Depreciation
A45: =A13 -> Assets | B45: =B38 -> Year 1 | C45: =C38 -> Year 2 | D45: =D38 -> Year 3 | E45: =E38 -> Year 4 | F45: =F38 -> Year 5
A46: =A14 -> Computer | B46: =E14*$D$14 -> 780 | C46: =F14*$D$14 -> 780 | D46: =G14*$D$14 -> 1430 | E46: =H14*$D$14 -> 1430 | F46: =I14*$D$14 -> 1560
A47: =A15 -> Printer | B47: =E15*$D$15 -> 164 | C47: =F15*$D$15 -> 164 | D47: =G15*$D$15 -> 328 | E47: =H15*$D$15 -> 328 | F47: =I15*$D$15 -> 328
A48: =A16 -> Office Furniture Set | B48: =E16*$D$16 -> 300 | C48: =F16*$D$16 -> 300 | D48: =G16*$D$16 -> 550 | E48: =H16*$D$16 -> 550 | F48: =I16*$D$16 -> 600
A49: =A17 -> Vehicle | B49: =E17*$D$17 -> 3500 | C49: =F17*$D$17 -> 3500 | D49: =G17*$D$17 -> 3500 | E49: =H17*$D$17 -> 3500 | F49: =I17*$D$17 -> 3500
A50: Total | B50: =SUM(B46:B49) -> 4744 | C50: =SUM(C46:C49) -> 4744 | D50: =SUM(D46:D49) -> 5808 | E50: =SUM(E46:E49) -> 5808 | F50: =SUM(F46:F49) -> 5988
A52: CapEx
...

Sheet Gross Income
A1: Margin | B1: 0.4
A3: Housing/Packages
A5: Housing/ Packages | B5: Cost | C5: Price | D5: Year 1 | E5: Year 2 | F5: Year 3 | G5: Year 4 | H5: Year 5
A6: "Bronze" | B6: 194 | C6: =ROUND(B6*(1+$B$1),0) -> 272 | D6: =ROUND(D$13*$I$6,0) -> 144 | E6: =ROUND(E$13*$I$6,0) -> 180 | F6: =ROUND(F$13*$I$6,0) -> 216 | G6: =ROUND(G$13*$I$6,0) -> 252 | H6: =ROUND(H$13*$I$6,0) -> 288 | I6: 0.6 | J6: Cost of "Bronze" accommodation is about 12000 Tenge per day, or 194 $ per weak
A7: "Silver" | B7: 448 | C7: =ROUND(B7*(1+$B$1),0) -> 627 | D7: =ROUND(D$13*$I$7,0) -> 72 | E7: =ROUND(E$13*$I$7,0) -> 90 | F7: =ROUND(F$13*$I$7,0) -> 108 | G7: =ROUND(G$13*$I$7,0) -> 126 | H7: =ROUND(H$13*$I$7,0) -> 144 | I7: 0.3 | J7: Reference
A8: "Gold" | B8: 1075 | C8: =ROUND(B8*(1+$B$1),0) -> 1505 | D8: =D13-SUM(D6:D7) -> 24 | E8: =E13-SUM(E6:E7) -> 30 | F8: =F13-SUM(F6:F7) -> 36 | G8: =G13-SUM(G6:G7) -> 42 | H8: =H13-SUM(H6:H7) -> 48 | I8: 0.1 | J8: Reference
A10: Medical Procedures
A12: Medical Procedures | B12: =B5 -> Cost | C12: =C5 -> Price | D12: =D5 -> Year 1 | E12: =E5 -> Year 2 | F12: =F5 -> Year 3 | G12: =G5 -> Year 4 | H12: =H5 -> Year 5
A13: Check-Up | B13: 10 | C13: =ROUND(B13*(1+$B$1),0) -> 14 | D13: 240 | E13: =D13+60 -> 300 | F13: =E13+60 -> 360 | G13: =F13+60 -> 420 | H13: =G13+60 -> 480 | I13: Number of Patients = Number of Check-Ups. We are expecting 20 patients per month. Increasing to 5 per year | N13: All the costs are average values of the procedures we found in the most popular dental clinics in Astana
A14: Cleaning | B14: 48 | C14: =ROUND(B14*(1+$B$1),0) -> 67 | D14: =D13 -> 240 | E14: =E13 -> 300 | F14: =F13 -> 360 | G14: =G13 -> 420 | H14: =H13 -> 480 | I14: Number of Cleaning = Number of Check-Ups
A15: Decay | B15: 30 | C15: =ROUND(B15*(1+$B$1),0) -> 42 | D15: =D13*2.5 -> 600 | E15: =E13*2.5 -> 750 | F15: =F13*2.5 -> 900 | G15: =G13*2.5 -> 1050 | H15: =H13*2.5 -> 1200 | I15: Number of Decay is about 2,5 per Patient
A16: Filling | B16: 92 | C16: =ROUND(B16*(1+$B$1),0) -> 129 | D16: =D15 -> 600 | E16: =E15 -> 750 | F16: =F15 -> 900 | G16: =G15 -> 1050 | H16: =H15 -> 1200 | I16: Number of Fillings=Number of Decay
A17: Crown | B17: 248 | C17: =ROUND(B17*(1+$B$1),0) -> 347 | D17: =D13/4 -> 60 | E17: =E13/4 -> 75 | F17: =F13/4 -> 90 | G17: =G13/4 -> 105 | H17: =H13/4 -> 120 | I17: Number of Crown is about every forth of Number of Patients
A18: Delete | B18: 76 | C18: =ROUND(B18*(1+$B$1),0) -> 106 | D18: =D13/10 -> 24 | E18: =E13/10 -> 30 | F18: =F13/10 -> 36 | G18: =G13/10 -> 42 | H18: =H13/10 -> 48 | I18: Every tenth of patient might require Deletion
A19: Surgical Delete | B19: 24 | C19: =ROUND(B19*(1+$B$1),0) -> 34 | D19: =D18*1.5 -> 36 | E19: =E18*1.5 -> 45 | F19: =F18*1.5 -> 54 | G19: =G18*1.5 -> 63 | H19: =H18*1.5 -> 72 | I19: Surgical Delete is about 1,5 times of Deletion
A20: Implants | B20: 545 | C20: =ROUND(B20*(1+$B$1),0) -> 763 | D20: =D18+D19/2 -> 42 | E20: =E18+E19/2 -> 52.5 | F20: =F18+F19/2 -> 63 | G20: =G18+G19/2 -> 73.5 | H20: =H18+H19/2 -> 84 | I20: Every Deletion needs implants, and half of the Surgical Deletion needs implants
A21: Plastins | B21: 151 | C21: =ROUND(B21*(1+$B$1),0) -> 211 | D21: =D22/3 -> 20 | E21: =E22/3 -> 25 | F21: =F22/3 -> 30 | G21: =G22/3 -> 35 | H21: =H22/3 -> 40 | I21: One third of the Braces
A22: Braces | B22: 303 | C22: =ROUND(B22*(1+$B$1),0) -> 424 | D22: =D13/4 -> 60 | E22: =E13/4 -> 75 | F22: =F13/4 -> 90 | G22: =G13/4 -> 105 | H22: =H13/4 -> 120 | I22: Every forth of Patients will need Braces (Most possible that it can be higher than we expected, as Braces can be most valuable procedure for Patients)
A23: Veneers | B23: 252 | C23: =ROUND(B23*(1+$B$1),0) -> 353 | D23: =D22/2 -> 30 | E23: =E22/2 -> 37.5 | F23: =F22/2 -> 45 | G23: =G22/2 -> 52.5 | H23: =H22/2 -> 60 | I23: Half of the Braces
A24: Full Reconstruction | B24: 6463 | C24: =ROUND(B24*(1+$B$1),0) -> 9048 | D24: =ROUND(D13/50,0) -> 5 | E24: =ROUND(E13/50,0) -> 6 | F24: =ROUND(F13/50,0) -> 7 | G24: =ROUND(G13/50,0) -> 8 | H24: =ROUND(H13/50,0) -> 10 | I24: 2% of Patients, as procedure is rare
A25: Other | B25: 10 | C25: =ROUND(B25*(1+$B$1),0) -> 14 | D25: =D13*1.5 -> 360 | E25: =E13*1.5 -> 450 | F25: =F13*1.5 -> 540 | G25: =G13*1.5 -> 630 | H25: =H13*1.5 -> 720 | I25: Includes anesthesia for procedures and etc.
A27: Revenue | H27: COGS
A29: Revenue | B29: =D12 -> Year 1 | C29: =E12 -> Year 2 | D29: =F12 -> Year 3 | E29: =G12 -> Year 4 | F29: =H12 -> Year 5 | H29: =A29 -> Revenue | I29: =B29 -> Year 1 | J29: =C29 -> Year 2 | K29: =D29 -> Year 3 | L29: =E29 -> Year 4 | M29: =F29 -> Year 5
A30: =A6 -> "Bronze" | B30: =$C$6*D6 -> 39168 | C30: =$C$6*E6 -> 48960 | D30: =$C$6*F6 -> 58752 | E30: =$C$6*G6 -> 68544 | F30: =$C$6*H6 -> 78336 | H30: =A30 -> "Bronze" | I30: =$B6*D6 -> 27936 | J30: =$B6*E6 -> 34920 | K30: =$B6*F6 -> 41904 | L30: =$B6*G6 -> 48888 | M30: =$B6*H6 -> 55872
A31: =A7 -> "Silver" | B31: =$C$7*D7 -> 45144 | C31: =$C$7*E7 -> 56430 | D31: =$C$7*F7 -> 67716 | E31: =$C$7*G7 -> 79002 | F31: =$C$7*H7 -> 90288 | H31: =A31 -> "Silver" | I31: =$B7*D7 -> 32256 | J31: =$B7*E7 -> 40320 | K31: =$B7*F7 -> 48384 | L31: =$B7*G7 -> 56448 | M31: =$B7*H7 -> 64512
A32: =A8 -> "Gold" | B32: =$C$8*D8 -> 36120 | C32: =$C$8*E8 -> 45150 | D32: =$C$8*F8 -> 54180 | E32: =$C$8*G8 -> 63210 | F32: =$C$8*H8 -> 72240 | H32: =A32 -> "Gold" | I32: =$B8*D8 -> 25800 | J32: =$B8*E8 -> 32250 | K32: =$B8*F8 -> 38700 | L32: =$B8*G8 -> 45150 | M32: =$B8*H8 -> 51600
A33: =A13 -> Check-Up | B33: =$C$13*D13 -> 3360 | C33: =$C$13*E13 -> 4200 | D33: =$C$13*F13 -> 5040 | E33: =$C$13*G13 -> 5880 | F33: =$C$13*H13 -> 6720 | H33: =A33 -> Check-Up | I33: =$B13*D13 -> 2400 | J33: =$B13*E13 -> 3000 | K33: =$B13*F13 -> 3600 | L33: =$B13*G13 -> 4200 | M33: =$B13*H13 -> 4800
A34: =A14 -> Cleaning | B34: =$C14*D14 -> 16080 | C34: =$C14*E14 -> 20100 | D34: =$C14*F14 -> 24120 | E34: =$C14*G14 -> 28140 | F34: =$C14*H14 -> 32160 | H34: =A34 -> Cleaning | I34: =$B14*D14 -> 11520 | J34: =$B14*E14 -> 14400 | K34: =$B14*F14 -> 17280 | L34: =$B14*G14 -> 20160 | M34: =$B14*H14 -> 23040
A35: =A15 -> Decay | B35: =$C15*D15 -> 25200 | C35: =$C15*E15 -> 31500 | D35: =$C15*F15 -> 37800 | E35: =$C15*G15 -> 44100 | F35: =$C15*H15 -> 50400 | H35: =A35 -> Decay | I35: =$B15*D15 -> 18000 | J35: =$B15*E15 -> 22500 | K35: =$B15*F15 -> 27000 | L35: =$B15*G15 -> 31500 | M35: =$B15*H15 -> 36000
A36: =A16 -> Filling | B36: =$C16*D16 -> 77400 | C36: =$C16*E16 -> 96750 | D36: =$C16*F16 -> 116100 | E36: =$C16*G16 -> 135450 | F36: =$C16*H16 -> 154800 | H36: =A36 -> Filling | I36: =$B16*D16 -> 55200 | J36: =$B16*E16 -> 69000 | K36: =$B16*F16 -> 82800 | L36: =$B16*G16 -> 96600 | M36: =$B16*H16 -> 110400
A37: =A17 -> Crown | B37: =$C17*D17 -> 20820 | C37: =$C17*E17 -> 26025 | D37: =$C17*F17 -> 31230 | E37: =$C17*G17 -> 36435 | F37: =$C17*H17 -> 41640 | H37: =A37 -> Crown | I37: =$B17*D17 -> 14880 | J37: =$B17*E17 -> 18600 | K37: =$B17*F17 -> 22320 | L37: =$B17*G17 -> 26040 | M37: =$B17*H17 -> 29760
A38: =A18 -> Delete | B38: =$C18*D18 -> 2544 | C38: =$C18*E18 -> 3180 | D38: =$C18*F18 -> 3816 | E38: =$C18*G18 -> 4452 | F38: =$C18*H18 -> 5088 | H38: =A38 -> Delete | I38: =$B18*D18 -> 1824 | J38: =$B18*E18 -> 2280 | K38: =$B18*F18 -> 2736 | L38: =$B18*G18 -> 3192 | M38: =$B18*H18 -> 3648
A39: =A19 -> Surgical Delete | B39: =$C19*D19 -> 1224 | C39: =$C19*E19 -> 1530 | D39: =$C19*F19 -> 1836 | E39: =$C19*G19 -> 2142 | F39: =$C19*H19 -> 2448 | H39: =A39 -> Surgical Delete | I39: =$B19*D19 -> 864 | J39: =$B19*E19 -> 1080 | K39: =$B19*F19 -> 1296 | L39: =$B19*G19 -> 1512 | M39: =$B19*H19 -> 1728
A40: =A20 -> Implants | B40: =$C20*D20 -> 32046 | C40: =$C20*E20 -> 40057.5 | D40: =$C20*F20 -> 48069 | E40: =$C20*G20 -> 56080.5 | F40: =$C20*H20 -> 64092 | H40: =A40 -> Implants | I40: =$B20*D20 -> 22890 | J40: =$B20*E20 -> 28612.5 | K40: =$B20*F20 -> 34335 | L40: =$B20*G20 -> 40057.5 | M40: =$B20*H20 -> 45780
A41: =A21 -> Plastins | B41: =$C21*D21 -> 4220 | C41: =$C21*E21 -> 5275 | D41: =$C21*F21 -> 6330 | E41: =$C21*G21 -> 7385 | F41: =$C21*H21 -> 8440 | H41: =A41 -> Plastins | I41: =$B21*D21 -> 3020 | J41: =$B21*E21 -> 3775 | K41: =$B21*F21 -> 4530 | L41: =$B21*G21 -> 5285 | M41: =$B21*H21 -> 6040
A42: =A22 -> Braces | B42: =$C22*D22 -> 25440 | C42: =$C22*E22 -> 31800 | D42: =$C22*F22 -> 38160 | E42: =$C22*G22 -> 44520 | F42: =$C22*H22 -> 50880 | H42: =A42 -> Braces | I42: =$B22*D22 -> 18180 | J42: =$B22*E22 -> 22725 | K42: =$B22*F22 -> 27270 | L42: =$B22*G22 -> 31815 | M42: =$B22*H22 -> 36360
A43: =A23 -> Veneers | B43: =$C23*D23 -> 10590 | C43: =$C23*E23 -> 13237.5 | D43: =$C23*F23 -> 15885 | E43: =$C23*G23 -> 18532.5 | F43: =$C23*H23 -> 21180 | H43: =A43 -> Veneers | I43: =$B23*D23 -> 7560 | J43: =$B23*E23 -> 9450 | K43: =$B23*F23 -> 11340 | L43: =$B23*G23 -> 13230 | M43: =$B23*H23 -> 15120
A44: =A24 -> Full Reconstruction | B44: =$C24*D24 -> 45240 | C44: =$C24*E24 -> 54288 | D44: =$C24*F24 -> 63336 | E44: =$C24*G24 -> 72384 | F44: =$C24*H24 -> 90480 | H44: =A44 -> Full Reconstruction | I44: =$B24*D24 -> 32315 | J44: =$B24*E24 -> 38778 | K44: =$B24*F24 -> 45241 | L44: =$B24*G24 -> 51704 | M44: =$B24*H24 -> 64630
A45: =A25 -> Other | B45: =$C25*D25 -> 5040 | C45: =$C25*E25 -> 6300 | D45: =$C25*F25 -> 7560 | E45: =$C25*G25 -> 8820 | F45: =$C25*H25 -> 10080 | H45: =A45 -> Other | I45: =$B25*D25 -> 3600 | J45: =$B25*E25 -> 4500 | K45: =$B25*F25 -> 5400 | L45: =$B25*G25 -> 6300 | M45: =$B25*H25 -> 7200
A46: Total | B46: =SUM(B30:B45) -> 389636 | C46: =SUM(C30:C45) -> 484783 | D46: =SUM(D30:D45) -> 579930 | E46: =SUM(E30:E45) -> 675077 | F46: =SUM(F30:F45) -> 779272 | H46: =A46 -> Total | I46: =SUM(I30:I45) -> 278245 | J46: =SUM(J30:J45) -> 346190.5 | K46: =SUM(K30:K45) -> 414136 | L46: =SUM(L30:L45) -> 482081.5 | M46: =SUM(M30:M45) -> 556490

Sheet Sheet1
