Workbook

Sheet Operating Expenses
A4: Salaries
A5: Position | B5: Salary | C5: Year 1 | D5: Year 2 | E5: Year 3 | F5: Year 4 | G5: Year 5 | H5: Reference
A6: Sofware Developer | B6: 500000 | C6: 1 | D6: 1 | E6: 1 | F6: 1 | G6: 1 | H6: link
A7: IT support | B7: 300000 | C7: 1 | D7: 1 | E7: 2 | F7: 3 | G7: 4 | H7: link
A8: External affair Manager | B8: 300000 | C8: 1 | D8: 1 | E8: 1 | F8: 1 | G8: 1 | H8: link
A9: Accountant | B9: 200000 | C9: 1 | D9: 1 | E9: 1 | F9: 1 | G9: 1 | H9: link
A10: Content Creator | B10: 200000 | C10: 1 | D10: 1 | E10: 1 | F10: 1 | G10: 1 | H10: link
A11: Customer Support | B11: 200000 | C11: 1 | D11: 1 | E11: 1 | F11: 2 | G11: 2 | H11: link
A13: Salaries Expenses | B13: 1 | C13: 2 | D13: 3 | E13: 4 | F13: 5
A14: Sofware Developer | B14: =(B6*12)*(1+'Income Statement and FCF'!$C7)^B13 -> 6420000 | C14: =(B6*12)*(1+'Income Statement and FCF'!$C7)^C13 -> 6869400 | D14: =(B6*12)*(1+'Income Statement and FCF'!$C7)^D13 -> 7350258 | E14: =(B6*12)*(1+'Income Statement and FCF'!$C7)^E13 -> 7864776.1 | F14: =(B6*12)*(1+'Income Statement and FCF'!$C7)^F13 -> 8415310.4
A15: IT support | B15: =($B$7*12)*(1+'Income Statement and FCF'!$C7)^B13 -> 3852000 | C15: =($B$7*12)*(1+'Income Statement and FCF'!$C7)^C13 -> 4121640 | D15: =($B$7*12*2)*(1+'Income Statement and FCF'!$C7)^D13 -> 8820309.6 | E15: =($B$7*12*3)*(1+'Income Statement and FCF'!$C7)^E13 -> 14156597 | F15: =($B$7*12 * 4)*(1+'Income Statement and FCF'!$C7)^F13 -> 20196745
A16: External affair Manager | B16: =($B$8*12)*(1+'Income Statement and FCF'!$C7)^B13 -> 3852000 | C16: =($B$8*12)*(1+'Income Statement and FCF'!$C7)^C13 -> 4121640 | D16: =($B$8*12)*(1+'Income Statement and FCF'!$C7)^D13 -> 4410154.8 | E16: =($B$8*12)*(1+'Income Statement and FCF'!$C7)^E13 -> 4718865.6 | F16: =($B$8*12)*(1+'Income Statement and FCF'!$C7)^F13 -> 5049186.2
A17: Accountant | B17: =($B$9*12)*(1+'Income Statement and FCF'!$C7) ^ B13 -> 2568000 | C17: =($B$9*12)*(1+'Income Statement and FCF'!$C7) ^ C13 -> 2747760 | D17: =($B$9*12)*(1+'Income Statement and FCF'!$C7) ^ D13 -> 2940103.2 | E17: =($B$9*12)*(1+'Income Statement and FCF'!$C7) ^ E13 -> 3145910.4 | F17: =($B$9*12)*(1+'Income Statement and FCF'!$C7) ^ F13 -> 3366124.2
A18: Content Creator | B18: =($B$10*12)*(1+'Income Statement and FCF'!$C7)^B13 -> 2568000 | C18: =($B$10*12)*(1+'Income Statement and FCF'!$C7)^C13 -> 2747760 | D18: =($B$10*12)*(1+'Income Statement and FCF'!$C7)^D13 -> 2940103.2 | E18: =($B$10*12)*(1+'Income Statement and FCF'!$C7)^E13 -> 3145910.4 | F18: =($B$10*12)*(1+'Income Statement and FCF'!$C7)^F13 -> 3366124.2
A19: Customer Support | B19: =($B$11*12)*(1+'Income Statement and FCF'!$C7)^B13 -> 2568000 | C19: =($B$11*12)*(1+'Income Statement and FCF'!$C7)^C13 -> 2747760 | D19: =($B$11*12)*(1+'Income Statement and FCF'!$C7)^D13 -> 2940103.2 | E19: =($B$11*12)*(1+'Income Statement and FCF'!$C7)^E13 -> 3145910.4 | F19: =($B$11*12)*(1+'Income Statement and FCF'!$C7)^F13 -> 3366124.2
A20: Total | B20: =SUM(B15:B19) -> 15408000 | C20: =SUM(C15:C19) -> 16486560 | D20: =SUM(D15:D19) -> 22050774 | E20: =SUM(E15:E19) -> 28313194 | F20: =SUM(F15:F19) -> 35344304
A22: Other Expenses | B22: Year 1 | C22: Year 2 | D22: Year 3 | E22: Year 4 | F22: Year 5 | G22: Reference
A23: Rent | B23: =7200000*(1+'Income Statement and FCF'!C9)^0 -> 7200000 | C23: =B23*(1+'Income Statement and FCF'!C9) -> 7905600 | D23: =C23*(1+'Income Statement and FCF'!C9) -> 8680348.8 | E23: =D23*(1+'Income Statement and FCF'!C9) -> 9531023 | F23: =E23*(1+'Income Statement and FCF'!C9) -> 10465063 | G23: link
A24: Advertisment | B24: 5000000 | C24: =B24 * (1+'Income Statement and FCF'!C7) -> 5350000 | D24: =C24 * (1+'Income Statement and FCF'!C7) -> 5724500 | E24: =D24 * (1+'Income Statement and FCF'!C7) -> 6125215 | F24: =E24 * (1+'Income Statement and FCF'!C7) -> 6553980.1 | G24: link
A25: Travel Expenses | B25: 16560000 | C25: =B25*(1+'Income Statement and FCF'!C7) -> 17719200 | D25: =C25*(1+'Income Statement and FCF'!C7) -> 18959544 | E25: =D25*(1+'Income Statement and FCF'!C5) -> 19528330 | F25: =E25*(1+'Income Statement and FCF'!C5) -> 20114180 | G25: link
A26: Amortization of app creation | B26: ='Income Statement and FCF'!C11/5 -> 24000000 | C26: ='Income Statement and FCF'!C11/5 -> 24000000 | D26: ='Income Statement and FCF'!C11/5 -> 24000000 | E26: ='Income Statement and FCF'!C11/5 -> 24000000 | F26: ='Income Statement and FCF'!C11/5 -> 24000000
A27: Total | B27: =SUM(B23:B26) -> 52760000 | C27: =SUM(C23:C26) -> 54974800 | D27: =SUM(D23:D26) -> 57364393 | E27: =SUM(E23:E26) -> 59184568 | F27: =SUM(F23:F26) -> 61133224
A29: Assets
A30: Fixed Assets | B30: Year 1 | C30: Year 2 | D30: Year 3 | E30: Year 4 | F30: Year 5
A31: Computer | B31: 0 | C31: 0 | D31: 4 | E31: 2 | F31: 2
A32: Monitor | B32: 0 | C32: 0 | D32: 4 | E32: 2 | F32: 2
A33: Telephones | B33: 0 | C33: 0 | D33: 2 | E33: 2 | F33: 2
A34: Printer | B34: 1 | C34: 0 | D34: 1 | E34: 0 | F34: 0
A36: Fixed Assets | B36: Cost | C36: Lifespan | D36: Depreciationper year | E36: Reference
A37: Computer | B37: 700000 | C37: 5 years | D37: =$B37/5 -> 140000 | E37: link
A38: Monitor | B38: 60000 | C38: 5 years | D38: =$B38/5 -> 12000 | E38: link
A39: Telephones | B39: 100000 | C39: 5 years | D39: =$B39/5 -> 20000 | E39: link
A40: Printer | B40: 120000 | C40: 5 years | D40: =$B40/5 -> 24000 | E40: link
A42: CapEx
A43: Fixed Assets | B43: Year 1 | C43: Year 2 | D43: Year 3 | E43: Year 4 | F43: Year 5
A44: Computer | B44: - | C44: - | D44: =B37*D31 -> 2800000 | E44: =B37*E31 -> 1400000 | F44: =B37*F31 -> 1400000
A45: Monitor | B45: - | C45: - | D45: =B38*D32 -> 240000 | E45: =E32*B38 -> 120000 | F45: =F32*B38 -> 120000
A46: Telephones | B46: - | C46: - | D46: =D33*B39 -> 200000 | E46: =B39*E33 -> 200000 | F46: =F33*B39 -> 200000
A47: Printers | B47: =B40*B34 -> 120000 | C47: - | D47: =B40*D34 -> 120000 | E47: - | F47: -
A48: Total | B48: =SUM(B44:B47) -> 120000 | C48: - | D48: =SUM(D44:D47) -> 3360000 | E48: =SUM(E44:E47) -> 1720000 | F48: =SUM(F44:F47) -> 1720000
...

Sheet Income Statement and FCF
A1: Assumptions | I1: Assumptions
A2: Tax | C2: 0.1
A3: Cost of Capital | C3: 0.2 | I3: 1)Rate of increasing of rent a year is decided to be 10%
A4: NWC | C4: 0.17 | I4: 2)rate of inflation is 7% is considered to Expense
A5: Growth Rate | C5: 0.03 | I5: 3) formula for increase of customers
A6: Increase in Salary | C6: 0.05 | I6: Let’s the formula for increase of customers be
A7: Increase in Other Expenses | C7: 0.07 | I7: N = 1000000*ln(0.00953*t+1)
A8: Inflation | C8: 0.07 | I8: where
A9: Increase in rent | C9: 0.098 | I9: 5) after two years we will hire 3 more it supports workers since amount of subscribers increase siginificantly
A10: Cost of Subscription | C10: 5000
A11: Creation of app | C11: 120000000 | D11: Link
A12: Cost of server per user | C12: 300
A13: Cost of maintaince of the app per user | C13: 390
A15: Income Statement
A16: Operations | C16: Year 1 | D16: Year 2 | E16: Year 3 | F16: Year 4 | G16: Year 5
A17: Sales | C17: ='Gross Income and cost of produc'!C6 -> 47425000 | D17: ='Gross Income and cost of produc'!D6 -> 94405000 | E17: ='Gross Income and cost of produc'!E6 -> 140945000 | F17: ='Gross Income and cost of produc'!F6 -> 187055000 | G17: ='Gross Income and cost of produc'!G6 -> 232750000
A18: COGS | C18: =-'Gross Income and cost of produc'!C13 -> -6544651 | D18: =-'Gross Income and cost of produc'!D13 -> -13939844 | E18: =-'Gross Income and cost of produc'!E13 -> -20219973 | F18: =-'Gross Income and cost of produc'!F13 -> -26834914 | G18: =-'Gross Income and cost of produc'!G13 -> -33390320
A19: Gross profit | C19: =C17+C18 -> 40880349 | D19: =D17+D18 -> 80465156 | E19: =E17+E18 -> 1.2072503e+08 | F19: =F17+F18 -> 1.6022009e+08 | G19: =G17+G18 -> 199359680
A20: Operating expenses
A21: Salaries | C21: =-'Operating Expenses'!B20 -> -15408000 | D21: =-'Operating Expenses'!C20 -> -16486560 | E21: =-'Operating Expenses'!D20 -> -22050774 | F21: =-'Operating Expenses'!E20 -> -28313194 | G21: =-'Operating Expenses'!F20 -> -35344304
A22: Depreciation | C22: =-'Operating Expenses'!B55 -> -24000 | D22: =-'Operating Expenses'!C55 -> -24000 | E22: =-'Operating Expenses'!D55 -> -696000 | F22: =-'Operating Expenses'!E55 -> -1040000 | G22: =-'Operating Expenses'!F55 -> -1384000
A23: Rent | C23: =-'Operating Expenses'!B23 -> -7200000 | D23: =-'Operating Expenses'!C23 -> -7905600 | E23: =-'Operating Expenses'!D23 -> -8680348.8 | F23: =-'Operating Expenses'!E23 -> -9531023 | G23: =-'Operating Expenses'!F23 -> -10465063
A24: Travel | C24: =-'Operating Expenses'!B25 -> -16560000 | D24: =-'Operating Expenses'!C25 -> -17719200 | E24: =-'Operating Expenses'!D25 -> -18959544 | F24: =-'Operating Expenses'!E25 -> -19528330 | G24: =-'Operating Expenses'!F25 -> -20114180
A25: Amortization of app creation | C25: =-'Operating Expenses'!B26 -> -24000000 | D25: =-'Operating Expenses'!C26 -> -24000000 | E25: =-'Operating Expenses'!D26 -> -24000000 | F25: =-'Operating Expenses'!E26 -> -24000000 | G25: =-'Operating Expenses'!F26 -> -24000000
A26: Advertisement | C26: =-'Operating Expenses'!B24 -> -5000000 | D26: =-'Operating Expenses'!C24 -> -5350000 | E26: =-'Operating Expenses'!D24 -> -5724500 | F26: =-'Operating Expenses'!E24 -> -6125215 | G26: =-'Operating Expenses'!F24 -> -6553980.1
A27: Total of operating expenses | C27: =SUM(C21:C26) -> -68192000 | D27: =SUM(D21:D26) -> -71485360 | E27: =SUM(E21:E26) -> -80111167 | F27: =SUM(F21:F26) -> -88537762 | G27: =SUM(G21:G26) -> -97861527
A28: EBIT | C28: =C19+C27 -> -27311651 | D28: =D19+D27 -> 8979795.7 | E28: =E19+E27 -> 40613860 | F28: =F19+F27 -> 71682324 | G28: =G19+G27 -> 1.0149815e+08
A29: Taxes | C29: =-C28*$C2 -> 2731165.1 | D29: =-D28*$C2 -> -897979.57 | E29: =-E28*$C2 -> -4061386 | F29: =-F28*$C2 -> -7168232.4 | G29: =-G28*$C2 -> -10149815
A30: Net Income | C30: =SUM(C28:C29) -> -24580486 | D30: =SUM(D28:D29) -> 8081816.1 | E30: =SUM(E28:E29) -> 36552474 | F30: =SUM(F28:F29) -> 64514091 | G30: =SUM(G28:G29) -> 91348338
A34: NWC | C34: =C17*$C$4 -> 8062250 | D34: =D17*$C$4 -> 16048850 | E34: =E17*$C$4 -> 23960650 | F34: =F17*$C$4 -> 31799350 | G34: =G17*$C$4 -> 39567500
A35: NWC Change | C35: =-C34 -> -8062250 | D35: =C34-D34 -> -7986600 | E35: =D34-E34 -> -7911800 | F35: =E34-F34 -> -7838700 | G35: =F34-G34 -> -7768150
A37: Operations | B37: 0 | C37: 1 | D37: 2 | E37: 3 | F37: 4 | G37: 5
A38: Unlevered Net Income | C38: =C30 -> -24580486 | D38: =D30 -> 8081816.1 | E38: =E30 -> 36552474 | F38: =F30 -> 64514091 | G38: =G30 -> 91348338
A39: Depreciation | C39: =-C22-C25 -> 24024000 | D39: =-D22-D25 -> 24024000 | E39: =-E22-E25 -> 24696000 | F39: =-F22-F25 -> 25040000 | G39: =-G22-G25 -> 25384000
A40: Capex | B40: =-C11 -> -120000000 | C40: =-'Operating Expenses'!B48 -> -120000 | D40: - | E40: =-'Operating Expenses'!D48 -> -3360000 | F40: =-'Operating Expenses'!E48 -> -1720000 | G40: =-'Operating Expenses'!F48 -> -1720000
A41: NWC | C41: =C35 -> -8062250 | D41: =D35 -> -7986600 | E41: =E35 -> -7911800 | F41: =F35 -> -7838700 | G41: =G35 -> -7768150
A42: FCF | B42: =SUM(B38:B41) -> -120000000 | C42: =SUM(C38:C41) -> -8738735.9 | D42: =SUM(D38:D41) -> 24119216 | E42: =SUM(E38:E41) -> 49976674 | F42: =SUM(F38:F41) -> 79995391 | G42: =SUM(G38:G41) -> 1.0724419e+08
A43: Terminal Value | G43: =(G42*(1+C5))/(C3-C5) -> 6.4977361e+08
A44: FCF with Terminal Value | B44: =SUM(B42:B43) -> -120000000 | C44: =SUM(C42:C43) -> -8738735.9 | D44: =SUM(D42:D43) -> 24119216 | E44: =SUM(E42:E43) -> 49976674 | F44: =SUM(F42:F43) -> 79995391 | G44: =SUM(G42:G43) -> 7.5701779e+08
A45: DCF | B45: =B44/(1+$C$3)^B37 -> -120000000 | C45: =C44/(1+$C$3)^C37 -> -7282279.9 | D45: =D44/(1+$C$3)^D37 -> 16749456 | E45: =E44/(1+$C$3)^E37 -> 28921687 | F45: =F44/(1+$C$3)^F37 -> 38578024 | G45: =G44/(1+$C$3)^G37 -> 3.0422847e+08
...

Sheet Gross Income and cost of produc
B2: Subscription
B4: Years | C4: 1 | D4: 2 | E4: 3 | F4: 4 | G4: 5
B5: Number of subscribers | C5: =ROUND(1000000*LN(0.00953*C4+1), 0) -> 9485 | D5: =ROUND(1000000*LN(0.00953*D4+1), 0) -> 18881 | E5: =ROUND(1000000*LN(0.00953*E4+1), 0) -> 28189 | F5: =ROUND(1000000*LN(0.00953*F4+1), 0) -> 37411 | G5: =ROUND(1000000*LN(0.00953*G4+1), 0) -> 46550
B6: Revenue | C6: =C5*('Income Statement and FCF'!$C10) -> 47425000 | D6: =D5*('Income Statement and FCF'!$C10) -> 94405000 | E6: =E5*('Income Statement and FCF'!$C10) -> 140945000 | F6: =F5*('Income Statement and FCF'!$C10) -> 187055000 | G6: =G5*('Income Statement and FCF'!$C10) -> 232750000
B9: Cost of good sold
B10: Years | C10: 1 | D10: 2 | E10: 3 | F10: 4 | G10: 5
B11: Servers | C11: =C5*'Income Statement and FCF'!$C12 -> 2845500 | D11: =D5*'Income Statement and FCF'!$C12*(1+'Income Statement and FCF'!C7) -> 6060801 | E11: =E5*'Income Statement and FCF'!$C12*(1+'Income Statement and FCF'!D7) -> 8456700 | F11: =F5*'Income Statement and FCF'!$C12*(1+'Income Statement and FCF'!E7) -> 11223300 | G11: =G5*'Income Statement and FCF'!$C12*(1+'Income Statement and FCF'!F7) -> 13965000 | H11: link
B12: Maintain of app | C12: =C5*'Income Statement and FCF'!$C13 -> 3699150 | D12: =D5*'Income Statement and FCF'!$C13*(1+'Income Statement and FCF'!$C$7) -> 7879041.3 | E12: =E5*'Income Statement and FCF'!$C13*(1+'Income Statement and FCF'!$C$7) -> 11763270 | F12: =F5*'Income Statement and FCF'!$C13*(1+'Income Statement and FCF'!$C$7) -> 15611610 | G12: =G5*'Income Statement and FCF'!$C13*(1+'Income Statement and FCF'!$C$7) -> 19425315 | H12: link
B13: Total | C13: =SUM(C10:C12) -> 6544651 | D13: =SUM(D10:D12) -> 13939844 | E13: =SUM(E10:E12) -> 20219973 | F13: =SUM(F10:F12) -> 26834914 | G13: =SUM(G10:G12) -> 33390320
